Workbook
Name Company: [1]Inputs!$A$8
Name EffDate: [1]Inputs!$A$5
Name LatestYear: [1]Inputs!$A$3
Name LOB: [1]Inputs!$A$9
Name Roman: #REF!
Name Roman: #REF!
Name Roman: #REF!
Name State: [1]Inputs!$A$7

Sheet Intro
B2: Workers Compensation Reserving Case Study
B4: A | C4: Introduction to Reserving (Loss Development)
C6: Step | D6: Tab Names | E6: Instructions
C7: 1 | D7: Summary | E7: 1.1 Read Chapter 5-7 of Friedland's textbook. Exhibit I of Chapter 7 can be referred to as an example;
E8: Friedland's textbook
E9: 1.2 The exhibits at the end of Chapter 7 of Friedland's textbook can be referred to as examples;
C10: 2 | D10: Base_Indem_Tri | E10: 2.1 Start with the given paid loss triangle and the incurred loss triangle, perform any data analysis required (such as identifying outliers);
E11: 2.2 Select incremental loss development factors for paid and incurred loss triangles in the blue cells;
E12: 2.3 Compare the selections for paid and incurred loss development factors in the '% of Ult' tab, and make adjustments as necessary;
C13: 3 | D13: Base_Med_Tri | E13: 3.1 Start with the given paid loss triangle and the incurred loss triangle, perform any data analysis required (such as identifying outliers);
E14: 3.2 Select incremental loss development factors for paid and incurred loss triangles in the blue cells;
E15: 3.3 Compare the selections for paid and incurred loss development factors in the '% of Ult' tab, and make adjustments as necessary;
C16: 4 | D16: Summary | E16: 4.1 Compare the results of the paid loss development method against the incurred loss development method;
E17: 4.2 Reflect on the reasons behind the differences, if any, and make adjustments as necessary;
E18: 4.3 Reflect and answer the questions in the case study;
B20: B | C20: In-Depth Considerations (Frequency/Severity, Catastrophe, and Tail Factor)
C22: Step | D22: Tab Names | E22: Instructions
C23: 1 | D23: Summary Freq&Sev | E23: 1.1 Read Chapter 11 of Friedland's textbook, feel free to skip over Frequency Severity Approach #2;
E24: Friedland's textbook
E25: 1.2 The exhibits at the end of Chapter 7 of Friedland's textbook can be referred to as examples;
C26: 2 | D26: Rep_Tri | E26: 2.1 Select incremental claim count development factors;
C27: 3 | E27: 3.1 Refer to Part A Step 2;
D28: Base_Indem_Sev | E28: 3.2 Consider the effect of the catastrophic event given in the 'Catastrophe" tab as well as tail factors in the yellow cells (development beyond the latest data in the triangle)
C29: 4 | D29: Base_Med_Sev | E29: 3.1 Refer to Part A Step 3;
E30: 3.2 Consider the effect of the catastrophic event given in the 'Catastrophe" tab as well as tail factors in the yellow cells (development beyond the latest data in the triangle)
C31: 5 | D31: Summary Freq&Sev | E31: 5.1 Compare the results of the frequency/severity method against the loss development method in part A;
E32: 5.2 Reflect and answer the questions in the case study;

Sheet Summary
B2: TOU Insurance Company - Workers Compensation
B3: Development of Unpaid Claim Estimate | Q3: Paid Loss Development | V3: Paid Loss Development
B4: Indemnity + Medical | Q4: Indemnity | V4: Medical
F6: Case | G6: Project Ultimate Claims | I6: Projected | K6: Unpaid Claim Estimate | Q6: Accident | R6: Paid | S6: Selected | T6: Ultimate | V6: Accident | W6: Paid | X6: Selected | Y6: Ultimate
B7: Accident | C7: Earned | D7: ="Claims at 12/31/" & B23 -> Claims at 12/31/2015 | F7: Outstanding | G7: Using Loss Development | I7: Ultimate Loss Ratios | K7: IBNR | M7: Total Unpaid | Q7: Year | R7: Losses | S7: LDFs | T7: Losses $000s | V7: Year | W7: Losses | X7: LDFs | Y7: Losses $000s
B8: Year | C8: Premiums | D8: Paid | E8: Reported | F8: ="At 12/31/" & B23 -> At 12/31/2015 | G8: Paid | H8: Reported | I8: Paid | J8: Reported | K8: Paid | L8: Reported | M8: Paid | N8: Reported | Q8: =Base_Indem_Tri!R8 -> 2003 | R8: =Base_Indem_Tri!AE8 -> 71881.089 | S8: =Base_Indem_Tri!$AE$57 -> 1.0000065 | T8: =R8*S8 -> 71881.556 | V8: =Q8 -> 2003 | W8: =Base_Med_Tri!AC8 -> 74815 | X8: =Base_Med_Tri!$AC$57 -> 1 | Y8: =W8*X8 -> 74815
B9: -1 | C9: =B9-1 -> -2 | D9: =C9-1 -> -3 | E9: =D9-1 -> -4 | F9: =E9-1 -> -5 | G9: =F9-1 -> -6 | H9: =G9-1 -> -7 | I9: =H9-1 -> -8 | J9: =I9-1 -> -9 | ... N9: =M9-1 -> -13 | Q9: =Base_Indem_Tri!R9 -> 2004 | R9: =Base_Indem_Tri!AD9 -> 72728.844 | S9: =Base_Indem_Tri!AD57 -> 1.0070065 | T9: =R9*S9 -> 73238.422 | V9: =Q9 -> 2004 | W9: =Base_Med_Tri!AB9 -> 74372 | X9: =Base_Med_Tri!AB57 -> 1.025 | Y9: =W9*X9 -> 76231.3
Q10: =Base_Indem_Tri!R10 -> 2005 | R10: =Base_Indem_Tri!AC10 -> 67848.685 | S10: =Base_Indem_Tri!AC57 -> 1.0269453 | T10: =R10*S10 -> 69676.886 | V10: =Q10 -> 2005 | W10: =Base_Med_Tri!AA10 -> 75063 | X10: =Base_Med_Tri!AA57 -> 1.04755 | Y10: =W10*X10 -> 78632.246
B11: =Q8 -> 2003 | C11: 206600 | D11: =R8+W8 -> 146696.09 | E11: =R28+W28 -> 146696 | F11: =E11-D11 -> -0.089 | G11: =T8+Y8 -> 146696.56 | H11: =T28+Y28 -> 146696 | I11: =G11/$C11 -> 0.7100511 | J11: =H11/$C11 -> 0.7100484 | K11: =G11-E11 -> 0.55622708 | L11: =H11-E11 -> 0 | M11: =K11+F11 -> 0.46722708 | N11: =L11+F11 -> -0.089 | Q11: =Base_Indem_Tri!R11 -> 2006 | R11: =Base_Indem_Tri!AB11 -> 64300.664 | S11: =Base_Indem_Tri!AB57 -> 1.0963392 | T11: =R11*S11 -> 70495.34 | V11: =Q11 -> 2006 | W11: =Base_Med_Tri!Z11 -> 73809 | X11: =Base_Med_Tri!Z57 -> 1.0695485 | Y11: =W11*X11 -> 78942.309
B12: =Q9 -> 2004 | C12: 210500 | D12: =R9+W9 -> 147100.84 | E12: =R29+W29 -> 150959 | F12: =E12-D12 -> 3858.1563 | G12: =T9+Y9 -> 149469.72 | H12: =T29+Y29 -> 150841.25 | I12: =G12/$C12 -> 0.71006994 | J12: =H12/$C12 -> 0.71658551 | K12: =G12-E12 -> -1489.2784 | L12: =H12-E12 -> -117.75 | M12: =K12+F12 -> 2368.878 | N12: =L12+F12 -> 3740.4063 | Q12: =Base_Indem_Tri!R12 -> 2007 | R12: =Base_Indem_Tri!AA12 -> 64477.685 | S12: =Base_Indem_Tri!AA57 -> 1.1154363 | T12: =R12*S12 -> 71920.749 | V12: =Q12 -> 2007 | W12: =Base_Med_Tri!Y12 -> 73620 | X12: =Base_Med_Tri!Y57 -> 1.0930786 | Y12: =W12*X12 -> 80472.448
B13: =Q10 -> 2005 | C13: 215000 | D13: =R10+W10 -> 142911.68 | E13: =R30+W30 -> 148987 | F13: =E13-D13 -> 6075.3154 | G13: =T10+Y10 -> 148309.13 | H13: =T30+Y30 -> 149712.54 | I13: =G13/$C13 -> 0.68980991 | J13: =H13/$C13 -> 0.69633739 | K13: =G13-E13 -> -677.86832 | L13: =H13-E13 -> 725.53872 | M13: =K13+F13 -> 5397.4471 | N13: =L13+F13 -> 6800.8542 | Q13: =Base_Indem_Tri!R13 -> 2008 | R13: =Base_Indem_Tri!Z13 -> 65727.56 | S13: =Base_Indem_Tri!Z57 -> 1.1358022 | T13: =R13*S13 -> 74653.507 | V13: =Q13 -> 2008 | W13: =Base_Med_Tri!X13 -> 71918 | X13: =Base_Med_Tri!X57 -> 1.1193125 | Y13: =W13*X13 -> 80498.717
B14: =Q11 -> 2006 | C14: 225300 | D14: =R11+W11 -> 138109.66 | E14: =R31+W31 -> 146038 | F14: =E14-D14 -> 7928.3362 | G14: =T11+Y11 -> 149437.65 | H14: =T31+Y31 -> 146782.85 | I14: =G14/$C14 -> 0.66328295 | J14: =H14/$C14 -> 0.65149954 | K14: =G14-E14 -> 3399.6491 | L14: =H14-E14 -> 744.84713 | M14: =K14+F14 -> 11327.985 | N14: =L14+F14 -> 8673.1833 | Q14: =Base_Indem_Tri!R14 -> 2009 | R14: =Base_Indem_Tri!Y14 -> 68110.91 | S14: =Base_Indem_Tri!Y57 -> 1.1568713 | T14: =R14*S14 -> 78795.558 | V14: =Q14 -> 2009 | W14: =Base_Med_Tri!W14 -> 75516 | X14: =Base_Med_Tri!W57 -> 1.1249091 | Y14: =W14*X14 -> 84948.633
B15: =Q12 -> 2007 | C15: 253500 | D15: =R12+W12 -> 138097.68 | E15: =R32+W32 -> 146506 | F15: =E15-D15 -> 8408.3155 | G15: =T12+Y12 -> 152393.2 | H15: =T32+Y32 -> 149127.21 | I15: =G15/$C15 -> 0.60115659 | J15: =H15/$C15 -> 0.58827303 | K15: =G15-E15 -> 5887.1965 | L15: =H15-E15 -> 2621.213 | M15: =K15+F15 -> 14295.512 | N15: =L15+F15 -> 11029.528 | Q15: =Base_Indem_Tri!R15 -> 2010 | R15: =Base_Indem_Tri!X15 -> 62485.197 | S15: =Base_Indem_Tri!X57 -> 1.1931971 | T15: =R15*S15 -> 74557.155 | V15: =Q15 -> 2010 | W15: =Base_Med_Tri!V15 -> 73984 | X15: =Base_Med_Tri!V57 -> 1.1294087 | Y15: =W15*X15 -> 83558.174
B16: =Q13 -> 2008 | C16: 253500 | D16: =R13+W13 -> 137645.56 | E16: =R33+W33 -> 146316 | F16: =E16-D16 -> 8670.4397 | G16: =T13+Y13 -> 155152.22 | H16: =T33+Y33 -> 151652.26 | I16: =G16/$C16 -> 0.61204033 | J16: =H16/$C16 -> 0.59823375 | K16: =G16-E16 -> 8836.2236 | L16: =H16-E16 -> 5336.2559 | M16: =K16+F16 -> 17506.663 | N16: =L16+F16 -> 14006.696 | Q16: =Base_Indem_Tri!R16 -> 2011 | R16: =Base_Indem_Tri!W16 -> 61009.463 | S16: =Base_Indem_Tri!W57 -> 1.2654452 | T16: =R16*S16 -> 77204.13 | V16: =Q16 -> 2011 | W16: =Base_Med_Tri!U16 -> 75968 | X16: =Base_Med_Tri!U57 -> 1.1407028 | Y16: =W16*X16 -> 86656.91
B17: =Q14 -> 2009 | C17: 267200 | D17: =R14+W14 -> 143626.91 | E17: =R34+W34 -> 154925 | F17: =E17-D17 -> 11298.09 | G17: =T14+Y14 -> 163744.19 | H17: =T34+Y34 -> 160094.24 | I17: =G17/$C17 -> 0.61281509 | J17: =H17/$C17 -> 0.59915508 | K17: =G17-E17 -> 8819.1915 | L17: =H17-E17 -> 5169.2386 | M17: =K17+F17 -> 20117.281 | N17: =L17+F17 -> 16467.329 | Q17: =Base_Indem_Tri!R17 -> 2012 | R17: =Base_Indem_Tri!V17 -> 54041 | S17: =Base_Indem_Tri!V57 -> 1.4165393 | T17: =R17*S17 -> 76551.201 | V17: =Q17 -> 2012 | W17: =Base_Med_Tri!T17 -> 88999 | X17: =Base_Med_Tri!T57 -> 1.1612354 | Y17: =W17*X17 -> 103348.79
B18: =Q15 -> 2010 | C18: 227700 | D18: =R15+W15 -> 136469.2 | E18: =R35+W35 -> 150888 | F18: =E18-D18 -> 14418.803 | G18: =T15+Y15 -> 158115.33 | H18: =T35+Y35 -> 155929.31 | I18: =G18/$C18 -> 0.69440197 | J18: =H18/$C18 -> 0.68480153 | K18: =G18-E18 -> 7227.3281 | L18: =H18-E18 -> 5041.3078 | M18: =K18+F18 -> 21646.131 | N18: =L18+F18 -> 19460.111 | Q18: =Base_Indem_Tri!R18 -> 2013 | R18: =Base_Indem_Tri!U18 -> 41159.998 | S18: =Base_Indem_Tri!U57 -> 1.7402097 | T18: =R18*S18 -> 71627.026 | V18: =Q18 -> 2013 | W18: =Base_Med_Tri!S18 -> 69375 | X18: =Base_Med_Tri!S57 -> 1.2227809 | Y18: =W18*X18 -> 84830.426
B19: =Q16 -> 2011 | C19: 225800 | D19: =R16+W16 -> 136977.46 | E19: =R36+W36 -> 157391 | F19: =E19-D19 -> 20413.537 | G19: =T16+Y16 -> 163861.04 | H19: =T36+Y36 -> 164244.04 | I19: =G19/$C19 -> 0.72569105 | J19: =H19/$C19 -> 0.72738723 | K19: =G19-E19 -> 6470.0397 | L19: =H19-E19 -> 6853.0355 | M19: =K19+F19 -> 26883.576 | N19: =L19+F19 -> 27266.572 | Q19: =Base_Indem_Tri!R19 -> 2014 | R19: =Base_Indem_Tri!T19 -> 26495.238 | S19: =Base_Indem_Tri!T57 -> 2.6855005 | T19: =R19*S19 -> 71152.975 | V19: =Q19 -> 2014 | W19: =Base_Med_Tri!R19 -> 64406 | X19: =Base_Med_Tri!R57 -> 1.3695146 | Y19: =W19*X19 -> 88204.959
B20: =Q17 -> 2012 | C20: 231900 | D20: =R17+W17 -> 143040 | E20: =R37+W37 -> 180452 | F20: =E20-D20 -> 37412 | G20: =T17+Y17 -> 179899.99 | H20: =T37+Y37 -> 188649.28 | I20: =G20/$C20 -> 0.77576539 | J20: =H20/$C20 -> 0.81349408 | K20: =G20-E20 -> -552.00587 | L20: =H20-E20 -> 8197.277 | M20: =K20+F20 -> 36859.994 | N20: =L20+F20 -> 45609.277 | Q20: =Base_Indem_Tri!R20 -> 2015 | R20: =Base_Indem_Tri!S20 -> 9643.9885 | S20: =Base_Indem_Tri!S57 -> 7.6002304 | T20: =R20*S20 -> 73296.534 | V20: =Q20 -> 2015 | W20: =Base_Med_Tri!Q20 -> 32877 | X20: =Base_Med_Tri!Q57 -> 2.6924658 | Y20: =W20*X20 -> 88520.197
B21: =Q18 -> 2013 | C21: 230100 | D21: =R18+W18 -> 110535 | E21: =R38+W38 -> 148527 | F21: =E21-D21 -> 37992.002 | G21: =T18+Y18 -> 156457.45 | H21: =T38+Y38 -> 156894.45 | I21: =G21/$C21 -> 0.67995416 | J21: =H21/$C21 -> 0.68185334 | K21: =G21-E21 -> 7930.4519 | L21: =H21-E21 -> 8367.4543 | M21: =K21+F21 -> 45922.454 | N21: =L21+F21 -> 46359.457
B22: =Q19 -> 2014 | C22: 253100 | D22: =R19+W19 -> 90901.238 | E22: =R39+W39 -> 143203 | F22: =E22-D22 -> 52301.762 | G22: =T19+Y19 -> 159357.93 | H22: =T39+Y39 -> 159352.29 | I22: =G22/$C22 -> 0.6296244 | J22: =H22/$C22 -> 0.62960208 | K22: =G22-E22 -> 16154.934 | L22: =H22-E22 -> 16149.286 | M22: =K22+F22 -> 68456.696 | N22: =L22+F22 -> 68451.048
B23: =Q20 -> 2015 | C23: 269000 | D23: =R20+W20 -> 42520.988 | E23: =R40+W40 -> 109127 | F23: =E23-D23 -> 66606.012 | G23: =T20+Y20 -> 161816.73 | H23: =T40+Y40 -> 160152.27 | I23: =G23/$C23 -> 0.60154919 | J23: =H23/$C23 -> 0.5953616 | K23: =G23-E23 -> 52689.731 | L23: =H23-E23 -> 51025.271 | M23: =K23+F23 -> 119295.74 | N23: =L23+F23 -> 117631.28 | Q23: Reported Loss Development | V23: Reported Loss Development
Q24: Indemnity | V24: Medical
B25: Total | C25: =SUM(C11:C23) -> 3069200 | D25: =SUM(D11:D23) -> 1654632.3 | E25: =SUM(E11:E23) -> 1930015 | F25: =SUM(F11:F23) -> 275382.68 | G25: =SUM(G11:G23) -> 2044711.1 | H25: =SUM(H11:H23) -> 2040128 | I25: =G25/$C25 -> 0.66620329 | J25: =H25/$C25 -> 0.66471001 | K25: =SUM(K11:K23) -> 114696.15 | L25: =SUM(L11:L23) -> 110112.98 | M25: =SUM(M11:M23) -> 390078.83 | N25: =SUM(N11:N23) -> 385495.65
Q26: Accident | R26: Reported | S26: Selected | T26: Ultimate | V26: Accident | W26: Reported | X26: Selected | Y26: Ultimate
B27: -1 | C27: Provided by Company XYZ | F27: =B33-1 -> -8 | G27: = (6) / (2) | Q27: Year | R27: Losses | S27: LDFs | T27: Losses $000s | V27: Year | W27: Losses | X27: LDFs | Y27: Losses $000s
B28: =B27-1 -> -2 | C28: Provided by Company XYZ | F28: =F27-1 -> -9 | G28: = (7) / (2) | Q28: =Base_Indem_Tri!A8 -> 2003 | R28: =Base_Indem_Tri!N8 -> 71881 | S28: =Base_Indem_Tri!$N$57 -> 1 | T28: =R28*S28 -> 71881 | V28: =Q28 -> 2003 | W28: =Base_Med_Tri!N8 -> 74815 | X28: =Base_Med_Tri!$N$57 -> 1 | Y28: =W28*X28 -> 74815
B29: =B28-1 -> -3 | C29: Provided by Company XYZ | F29: =F28-1 -> -10 | G29: = (6) - (4) | Q29: =Base_Indem_Tri!A9 -> 2004 | R29: =Base_Indem_Tri!M9 -> 73970 | S29: =Base_Indem_Tri!M57 -> 0.988 | T29: =R29*S29 -> 73082.36 | V29: =Q29 -> 2004 | W29: =Base_Med_Tri!M9 -> 76989 | X29: =Base_Med_Tri!M57 -> 1.01 | Y29: =W29*X29 -> 77758.89
B30: =B29-1 -> -4 | C30: Provided by Company XYZ | F30: =F29-1 -> -11 | G30: = (7) - (4) | Q30: =Base_Indem_Tri!A10 -> 2005 | R30: =Base_Indem_Tri!L10 -> 70034 | S30: =Base_Indem_Tri!L57 -> 0.99339315 | T30: =R30*S30 -> 69571.296 | V30: =Q30 -> 2005 | W30: =Base_Med_Tri!L10 -> 78953 | X30: =Base_Med_Tri!L57 -> 1.01505 | Y30: =W30*X30 -> 80141.243
B31: =B30-1 -> -5 | C31: = (4) - (3) | F31: =F30-1 -> -12 | G31: = (5) + (10) | Q31: =Base_Indem_Tri!A11 -> 2006 | R31: =Base_Indem_Tri!K11 -> 67340 | S31: =Base_Indem_Tri!K57 -> 0.98754129 | T31: =R31*S31 -> 66501.03 | V31: =Q31 -> 2006 | W31: =Base_Med_Tri!K11 -> 78698 | X31: =Base_Med_Tri!K57 -> 1.0201252 | Y31: =W31*X31 -> 80281.817
B32: =B31-1 -> -6 | C32: Selected by Actuary | F32: =F31-1 -> -13 | G32: = (5) + (11) | Q32: =Base_Indem_Tri!A12 -> 2007 | R32: =Base_Indem_Tri!J12 -> 68355 | S32: =Base_Indem_Tri!J57 -> 0.98734596 | T32: =R32*S32 -> 67490.033 | V32: =Q32 -> 2007 | W32: =Base_Med_Tri!J12 -> 78151 | X32: =Base_Med_Tri!J57 -> 1.0446083 | Y32: =W32*X32 -> 81637.18
B33: =B32-1 -> -7 | C33: Selected by Actuary | Q33: =Base_Indem_Tri!A13 -> 2008 | R33: =Base_Indem_Tri!I13 -> 70556 | S33: =Base_Indem_Tri!I57 -> 0.99408341 | T33: =R33*S33 -> 70138.549 | V33: =Q33 -> 2008 | W33: =Base_Med_Tri!I13 -> 75760 | X33: =Base_Med_Tri!I57 -> 1.0759465 | Y33: =W33*X33 -> 81513.707
Q34: =Base_Indem_Tri!A14 -> 2009 | R34: =Base_Indem_Tri!H14 -> 74956 | S34: =Base_Indem_Tri!H57 -> 0.98678999 | T34: =R34*S34 -> 73965.83 | V34: =Q34 -> 2009 | W34: =Base_Med_Tri!H14 -> 79969 | X34: =Base_Med_Tri!H57 -> 1.0770225 | Y34: =W34*X34 -> 86128.408
Q35: =Base_Indem_Tri!A15 -> 2010 | R35: =Base_Indem_Tri!G15 -> 71116 | S35: =Base_Indem_Tri!G57 -> 0.98449115 | T35: =R35*S35 -> 70013.073 | V35: =Q35 -> 2010 | W35: =Base_Med_Tri!G15 -> 79772 | X35: =Base_Med_Tri!G57 -> 1.0770225 | Y35: =W35*X35 -> 85916.235
Q36: =Base_Indem_Tri!A16 -> 2011 | R36: =Base_Indem_Tri!F16 -> 73881 | S36: =Base_Indem_Tri!F57 -> 0.97891425 | T36: =R36*S36 -> 72323.163 | V36: =Q36 -> 2011 | W36: =Base_Med_Tri!F16 -> 83510 | X36: =Base_Med_Tri!F57 -> 1.1007169 | Y36: =W36*X36 -> 91920.872
Q37: =Base_Indem_Tri!A17 -> 2012 | R37: =Base_Indem_Tri!E17 -> 81043 | S37: =Base_Indem_Tri!E57 -> 0.97760579 | T37: =R37*S37 -> 79228.106 | V37: =Q37 -> 2012 | W37: =Base_Med_Tri!E17 -> 99409 | X37: =Base_Med_Tri!E57 -> 1.1007169 | Y37: =W37*X37 -> 109421.17
Q38: =Base_Indem_Tri!A18 -> 2013 | R38: =Base_Indem_Tri!D18 -> 65798 | S38: =Base_Indem_Tri!D57 -> 1.0005356 | T38: =R38*S38 -> 65833.242 | V38: =Q38 -> 2013 | W38: =Base_Med_Tri!D18 -> 82729 | X38: =Base_Med_Tri!D57 -> 1.1007169 | Y38: =W38*X38 -> 91061.212
Q39: =Base_Indem_Tri!A19 -> 2014 | R39: =Base_Indem_Tri!C19 -> 58387 | S39: =Base_Indem_Tri!C57 -> 1.1158931 | T39: =R39*S39 -> 65153.652 | V39: =Q39 -> 2014 | W39: =Base_Med_Tri!C19 -> 84816 | X39: =Base_Med_Tri!C57 -> 1.1106234 | Y39: =W39*X39 -> 94198.634
Q40: =Base_Indem_Tri!A20 -> 2015 | R40: =Base_Indem_Tri!B20 -> 43013 | S40: =Base_Indem_Tri!B57 -> 1.5263002 | T40: =R40*S40 -> 65650.75 | V40: =Q40 -> 2015 | W40: =Base_Med_Tri!B20 -> 66114 | X40: =Base_Med_Tri!B57 -> 1.4293723 | Y40: =W40*X40 -> 94501.521

Sheet Base_Indem_Tri
T1: 32289 | U1: 50188 | V1: 62041
B2: Direct Accident Year Case Reported Loss Development Factors | S2: Direct Accident Year Paid Loss Development Factors | AF2: 9.8243
B3: INDEMNITY in $Thousands (2004 Dollars) | S3: INDEMNITY in $Thousands | AF3: 0.0937 | AJ3: Inflation Rates
C4: =68446-4000 -> 64446 | D4: =78366-6000 -> 72366 | E4: =81043-8000 -> 73043 | T4: =T17-4000 -> 24289 | U4: =U17-6000 -> 38188 | V4: =V17-8000 -> 46041 | AY4: Cummulative
A5: Accident | R5: Accident | AJ5: Year | AK5: Inflation % | AL5: Cummulative Inflation | AO5: reported | AP5: 861263 | AY5: Time | AZ5: Paid Rate | BA5: Reported Rate
A6: Year | B6: 12 | C6: 24 | D6: 36 | E6: 48 | F6: 60 | G6: 72 | H6: 84 | I6: 96 | J6: 108 | K6: 120 | L6: 132 | M6: 144 | N6: 156 | O6: Ultimate | P6: total sum | R6: Year | S6: 12 | T6: 24 | U6: 36 | V6: 48 | W6: 60 | X6: 72 | Y6: 84 | Z6: 96 | AA6: 108 | AB6: 120 | AC6: 132 | AD6: 144 | AE6: 156 | AF6: Ultimate | AG6: total | AH6: =SUM(AF8:AF20)-AF17+AG17 -> 988232.88 | AO6: paid | AP6: 988232 | AY6: 156 | AZ6: =1 + 9.8243 * EXP(-0.0937*AY6) -> 1.0000044 | BA6: =0.9864+0.3978*EXP(-1.3083*AY6) -> 0.9864
AY7: =AY6+12 -> 168 | AZ7: =1 + 9.8243 * EXP(-0.0937*AY7) -> 1.0000014 | BA7: =0.9864+0.3978*EXP(-1.3083*AY7) -> 0.9864
A8: 2003 | I8: 70541 | J8: 71920 | K8: 72610 | L8: 71234 | M8: 72600 | N8: 71881 | O8: =N8 -> 71881 | P8: =SUM(O8:O20) -> 861262.76 | R8: 2003 | Z8: 66618.247 | AA8: 68315.439 | AB8: 69881.816 | AC8: 69881.816 | AD8: 71381.512 | AE8: 71881.089 | AF8: =AE8*1.0000065 -> 71881.556 | AY8: =AY7+12 -> 180 | AZ8: =1 + 9.8243 * EXP(-0.0937*AY8) -> 1.0000005 | BA8: =0.9864+0.3978*EXP(-1.3083*AY8) -> 0.9864
A9: 2004 | H9: 69295 | I9: 68810 | J9: 72057 | K9: 72752 | L9: 74586 | M9: 73970 | N9: =M9*0.988 -> 73082.36 | O9: =N9 -> 73082.36 | R9: 2004 | Y9: 64521.02 | Z9: 65488.835 | AA9: 67935.673 | AB9: 68906.784 | AC9: 71345.865 | AD9: 72728.844 | AE9: =AD9*1.007 -> 73237.946 | AF9: =AE9*1.0000065 -> 73238.422 | AY9: =AY8+12 -> 192 | AZ9: =1 + 9.8243 * EXP(-0.0937*AY9) -> 1.0000002 | BA9: =0.9864+0.3978*EXP(-1.3083*AY9) -> 0.9864
A10: 2005 | G10: 70202 | H10: 69641 | I10: 69501 | J10: 69047 | K10: 70449 | L10: 70034 | M10: =L10*0.997 -> 69823.898 | N10: =M10*0.988 -> 68986.011 | O10: =N10 -> 68986.011 | R10: 2005 | X10: 61869.596 | Y10: 63725.684 | Z10: 65127.649 | AA10: 65354.779 | AB10: 67075.927 | AC10: 67848.685 | AD10: =AC10*1.02 -> 69205.658 | AE10: =AD10*1.007 -> 69690.098 | AF10: =AE10*1.0000065 -> 69690.551 | AY10: =AY9+12 -> 204 | AZ10: =1 + 9.8243 * EXP(-0.0937*AY10) -> 1 | BA10: =0.9864+0.3978*EXP(-1.3083*AY10) -> 0.9864
A11: 2006 | F11: 68892 | G11: 68272 | H11: 67384 | I11: 67587 | J11: 68023 | K11: 67340 | L11: =K11*0.992 -> 66801.28 | M11: =L11*0.997 -> 66600.876 | N11: =M11*0.988 -> 65801.666 | O11: =N11 -> 65801.666 | R11: 2006 | W11: 55420.944 | X11: 58746.2 | Y11: 60626.079 | Z11: 62141.731 | AA11: 63606.318 | AB11: 64300.664 | AC11: =AB11*1.068 -> 68673.109 | AD11: =AC11*1.02 -> 70046.571 | AE11: =AD11*1.007 -> 70536.897 | AF11: =AE11*1.0000065 -> 70537.356 | AY11: =AY10+12 -> 216 | AZ11: =1 + 9.8243 * EXP(-0.0937*AY11) -> 1 | BA11: =0.9864+0.3978*EXP(-1.3083*AY11) -> 0.9864
A12: 2007 | E12: 69499 | F12: 69569 | G12: 69221 | H12: 69429 | I12: 68735 | J12: 68355 | K12: =J12*0.991 -> 67739.805 | L12: =K12*0.992 -> 67197.887 | M12: =L12*0.997 -> 66996.293 | N12: =M12*0.988 -> 66192.337 | O12: =N12 -> 66192.337 | R12: 2007 | V12: 50694.623 | W12: 56524.504 | X12: 60255.122 | Y12: 62665.327 | Z12: 63730.637 | AA12: 64477.685 | AB12: =AA12*1.017 -> 65573.805 | AC12: =AB12*1.068 -> 70032.824 | AD12: =AC12*1.02 -> 71433.48 | AE12: =AD12*1.007 -> 71933.515 | AF12: =AE12*1.0000065 -> 71933.982 | AJ12: 2010 | AK12: 1.64 | AL12: =1 +AK12/100 -> 1.0164 | AM12: 1.0164 | AY12: =AY11+12 -> 228 | AZ12: =1 + 9.8243 * EXP(-0.0937*AY12) -> 1 | BA12: =0.9864+0.3978*EXP(-1.3083*AY12) -> 0.9864
A13: 2008 | D13: 69207 | E13: 71629 | F13: 71915 | G13: 71412 | H13: 71269 | I13: 70556 | J13: =I13*0.992 -> 69991.552 | K13: =J13*0.991 -> 69361.628 | L13: =K13*0.992 -> 68806.735 | M13: =L13*0.997 -> 68600.315 | N13: =M13*0.988 -> 67777.111 | O13: =N13 -> 67777.111 | R13: 2008 | U13: 43162.458 | V13: 52312.9 | W13: 59479.767 | X13: 62870.114 | Y13: 64756.217 | Z13: 65727.56 | AA13: =Z13*1.018 -> 66910.656 | AB13: =AA13*1.017 -> 68048.138 | AC13: =AB13*1.068 -> 72675.411 | AD13: =AC13*1.02 -> 74128.919 | AE13: =AD13*1.007 -> 74647.822 | AF13: =AE13*1.0000065 -> 74648.307 | AJ13: 2011 | AK13: 3.16 | AL13: =AL12*(1+AK13/100) -> 1.0485182 | AM13: 1.04518 | AY13: =AY12+12 -> 240 | AZ13: =1 + 9.8243 * EXP(-0.0937*AY13) -> 1 | BA13: =0.9864+0.3978*EXP(-1.3083*AY13) -> 0.9864
A14: 2009 | C14: 66891 | D14: 73513 | E14: 75939 | F14: 75635 | G14: 75257 | H14: 74956 | I14: =H14*0.979 -> 73381.924 | J14: =I14*0.992 -> 72794.869 | K14: =J14*0.991 -> 72139.715 | L14: =K14*0.992 -> 71562.597 | M14: =L14*0.997 -> 71347.909 | N14: =M14*0.988 -> 70491.734 | O14: =N14 -> 70491.734 | R14: 2009 | T14: 29996.407 | U14: 45234.582 | V14: 55909.943 | W14: 62507.317 | X14: 66320.263 | Y14: 68110.91 | Z14: =Y14*1.019 -> 69405.017 | AA14: =Z14*1.018 -> 70654.308 | AB14: =AA14*1.017 -> 71855.431 | AC14: =AB14*1.068 -> 76741.6 | AD14: =AC14*1.02 -> 78276.432 | AE14: =AD14*1.007 -> 78824.367 | AF14: =AE14*1.0000065 -> 78824.88 | AJ14: 2012 | AK14: 2.07 | AL14: =AL13*(1+AK14/100) -> 1.0702226 | AM14: 1.070223 | AY14: =AY13+12 -> 252 | AZ14: =1 + 9.8243 * EXP(-0.0937*AY14) -> 1 | BA14: =0.9864+0.3978*EXP(-1.3083*AY14) -> 0.9864
A15: 2010 | B15: 47025 | C15: 62026 | D15: 68849 | E15: 71259 | F15: 70974 | G15: 71116 | H15: =G15*0.978 -> 69551.448 | I15: =H15*0.979 -> 68090.868 | J15: =I15*0.992 -> 67546.141 | K15: =J15*0.991 -> 66938.225 | L15: =K15*0.992 -> 66402.72 | M15: =L15*0.997 -> 66203.511 | N15: =M15*0.988 -> 65409.069 | O15: =N15 -> 65409.069 | R15: 2010 | S15: 10418.129 | T15: 27680.969 | U15: 42905.503 | V15: 52773.768 | W15: 58948.299 | X15: 62485.197 | Y15: =X15*1.031 -> 64422.238 | Z15: =Y15*1.019 -> 65646.261 | AA15: =Z15*1.018 -> 66827.893 | AB15: =AA15*1.017 -> 67963.967 | AC15: =AB15*1.068 -> 72585.517 | AD15: =AC15*1.02 -> 74037.228 | AE15: =AD15*1.007 -> 74555.488 | AF15: =AE15*1.0000065 -> 74555.973 | AJ15: 2013 | AK15: 1.5 | AL15: =AL14*(1+AK15/100) -> 1.0862759 | AM15: 1.086276 | AY15: =AY14+12 -> 264 | AZ15: =1 + 9.8243 * EXP(-0.0937*AY15) -> 1 | BA15: =0.9864+0.3978*EXP(-1.3083*AY15) -> 0.9864
A16: 2011 | B16: 46781 | C16: 63996 | D16: 71227 | E16: 73222 | F16: 73881 | G16: =F16*0.976 -> 72107.856 | H16: =G16*0.978 -> 70521.483 | I16: =H16*0.979 -> 69040.532 | J16: =I16*0.992 -> 68488.208 | K16: =J16*0.991 -> 67871.814 | L16: =K16*0.992 -> 67328.839 | M16: =L16*0.997 -> 67126.853 | N16: =M16*0.988 -> 66321.331 | O16: =N16 -> 66321.331 | R16: 2011 | S16: 10469.768 | T16: 28634.815 | U16: 44269.423 | V16: 54717.007 | W16: 61009.463 | X16: =W16*1.061 -> 64731.04 | Y16: =X16*1.031 -> 66737.703 | Z16: =Y16*1.019 -> 68005.719 | AA16: =Z16*1.018 -> 69229.822 | AB16: =AA16*1.017 -> 70406.729 | AC16: =AB16*1.068 -> 75194.387 | AD16: =AC16*1.02 -> 76698.274 | AE16: =AD16*1.007 -> 77235.162 | AF16: =AE16*1.0000065 -> 77235.664 | AJ16: 2014 | AK16: 1.6 | AL16: =AL15*(1+AK16/100) -> 1.1036563 | AM16: 1.103656 | AY16: =AY15+12 -> 276 | AZ16: =1 + 9.8243 * EXP(-0.0937*AY16) -> 1 | BA16: =0.9864+0.3978*EXP(-1.3083*AY16) -> 0.9864
A17: 2012 | B17: 46352 | C17: 68446 | D17: 78366 | E17: 81043 | F17: =E17*0.981 -> 79503.183 | G17: =F17*0.976 -> 77595.107 | H17: =G17*0.978 -> 75888.014 | I17: =H17*0.979 -> 74294.366 | J17: =I17*0.992 -> 73700.011 | K17: =J17*0.991 -> 73036.711 | L17: =K17*0.992 -> 72452.417 | M17: =L17*0.997 -> 72235.06 | N17: =M17*0.988 -> 71368.239 | O17: =N17 -> 71368.239 | R17: 2012 | S17: 9887.831 | T17: 28289 | U17: 44188 | V17: 54041 | W17: =V1*1.119 -> 69423.879 | X17: =W17*1.061 -> 73658.736 | Y17: =X17*1.031 -> 75942.156 | Z17: =Y17*1.019 -> 77385.057 | AA17: =Z17*1.018 -> 78777.988 | AB17: =AA17*1.017 -> 80117.214 | AC17: =AB17*1.068 -> 85565.185 | AD17: =AC17*1.02 -> 87276.488 | AE17: =AD17*1.007 -> 87887.424 | AF17: =AE17*1.0000065 -> 87887.995 | AG17: =AF17+8000 -> 95887.995 | AJ17: 2015 | AK17: 0.18 | AL17: =AL16*(1+AK17/100) -> 1.1056429 | AM17: 1.105643 | AY17: =AY16+12 -> 288 | AZ17: =1 + 9.8243 * EXP(-0.0937*AY17) -> 1 | BA17: =0.9864+0.3978*EXP(-1.3083*AY17) -> 0.9864
A18: 2013 | B18: 42577 | C18: 57266 | D18: 65798 | E18: =D18*1.01 -> 66455.98 | F18: =E18*0.981 -> 65193.316 | G18: =F18*0.976 -> 63628.677 | H18: =G18*0.978 -> 62228.846 | I18: =H18*0.979 -> 60922.04 | J18: =I18*0.992 -> 60434.664 | K18: =J18*0.991 -> 59890.752 | L18: =K18*0.992 -> 59411.626 | M18: =L18*0.997 -> 59233.391 | N18: =M18*0.988 -> 58522.59 | O18: =N18 -> 58522.59 | R18: 2013 | S18: 9300.4543 | T18: 26831.811 | U18: 41159.998 | V18: =U18*U49 -> 50564.799 | W18: =V18*1.19 -> 60172.111 | X18: =W18*1.061 -> 63842.609 | Y18: =X18*1.031 -> 65821.73 | Z18: =Y18*1.019 -> 67072.343 | AA18: =Z18*1.018 -> 68279.645 | AB18: =AA18*1.017 -> 69440.399 | AC18: =AB18*1.068 -> 74162.347 | AD18: =AC18*1.02 -> 75645.593 | AE18: =AD18*1.007 -> 76175.113 | AF18: =AE18*1.0000065 -> 76175.608 | AY18: =AY17+12 -> 300 | AZ18: =1 + 9.8243 * EXP(-0.0937*AY18) -> 1 | BA18: =0.9864+0.3978*EXP(-1.3083*AY18) -> 0.9864
A19: 2014 | B19: 38744 | C19: 58387 | D19: =C19*1.101 -> 64284.087 | E19: =D19*1.01 -> 64926.928 | F19: =E19*0.981 -> 63693.316 | G19: =F19*0.976 -> 62164.677 | H19: =G19*0.978 -> 60797.054 | I19: =H19*0.979 -> 59520.316 | J19: =I19*0.992 -> 59044.153 | K19: =J19*0.991 -> 58512.756 | L19: =K19*0.992 -> 58044.654 | M19: =L19*0.997 -> 57870.52 | N19: =M19*0.988 -> 57176.073 | O19: =N19 -> 57176.073 | R19: 2014 | S19: 9235.008 | T19: 26495.238 | U19: =T19*T49 -> 40887.588 | V19: =U19*U49 -> 50230.145 | W19: =V19*1.19 -> 59773.873 | X19: =W19*1.061 -> 63420.079 | Y19: =X19*1.031 -> 65386.101 | Z19: =Y19*1.019 -> 66628.437 | AA19: =Z19*1.018 -> 67827.749 | AB19: =AA19*1.017 -> 68980.821 | AC19: =AB19*1.068 -> 73671.517 | AD19: =AC19*1.02 -> 75144.947 | AE19: =AD19*1.007 -> 75670.961 | AF19: =AE19*1.0000065 -> 75671.453 | AY19: =AY18+12 -> 312 | AZ19: =1 + 9.8243 * EXP(-0.0937*AY19) -> 1 | BA19: =0.9864+0.3978*EXP(-1.3083*AY19) -> 0.9864
A20: 2015 | B20: 43013 | C20: =B20*1.383 -> 59486.979 | D20: =C20*1.101 -> 65495.164 | E20: =D20*1.01 -> 66150.116 | F20: =E20*0.981 -> 64893.263 | G20: =F20*0.976 -> 63335.825 | H20: =G20*0.978 -> 61942.437 | I20: =H20*0.979 -> 60641.646 | J20: =I20*0.992 -> 60156.513 | K20: =J20*0.991 -> 59615.104 | L20: =K20*0.992 -> 59138.183 | M20: =L20*0.997 -> 58960.769 | N20: =M20*0.988 -> 58253.239 | O20: =N20 -> 58253.239 | R20: 2015 | S20: 9643.9885 | T20: =S20*S49 -> 27293.435 | U20: =T20*T49 -> 42119.37 | V20: =U20*U49 -> 51743.381 | W20: =V20*1.19 -> 61574.624 | X20: =W20*1.061 -> 65330.676 | Y20: =X20*1.031 -> 67355.927 | Z20: =Y20*1.019 -> 68635.689 | AA20: =Z20*1.018 -> 69871.132 | AB20: =AA20*1.017 -> 71058.941 | AC20: =AB20*1.068 -> 75890.949 | AD20: =AC20*1.02 -> 77408.768 | AE20: =AD20*1.007 -> 77950.629 | AF20: =AE20*1.0000065 -> 77951.136 | AY20: =AY19+12 -> 324 | AZ20: =1 + 9.8243 * EXP(-0.0937*AY20) -> 1 | BA20: =0.9864+0.3978*EXP(-1.3083*AY20) -> 0.9864
AY21: =AY20+12 -> 336 | AZ21: =1 + 9.8243 * EXP(-0.0937*AY21) -> 1 | BA21: =0.9864+0.3978*EXP(-1.3083*AY21) -> 0.9864
AY22: =AY21+12 -> 348 | AZ22: =1 + 9.8243 * EXP(-0.0937*AY22) -> 1 | BA22: =0.9864+0.3978*EXP(-1.3083*AY22) -> 0.9864
AF23: 0.1, 0.15, 0.20, 0.25, 0.3 | AY23: =AY22+12 -> 360 | AZ23: =1 + 9.8243 * EXP(-0.0937*AY23) -> 1 | BA23: =0.9864+0.3978*EXP(-1.3083*AY23) -> 0.9864
B24: Target - Direct Accident Year Case Reported Loss Development Factors | S24: Target - Direct Accident Year Paid Loss Development Factors | AF24: 0.1, 0.2, 0.3, 0.4 | AK24: Inflation Adjusted Direct Accident Year Paid Loss Development Factors | AY24: =AY23+12 -> 372 | AZ24: =1 + 9.8243 * EXP(-0.0937*AY24) -> 1 | BA24: =0.9864+0.3978*EXP(-1.3083*AY24) -> 0.9864
B25: INDEMNITY | S25: INDEMNITY | AF25: 0.2, 0.35, 0.45 | AK25: INDEMNITY in $Thousands | AY25: =AY24+12 -> 384 | AZ25: =1 + 9.8243 * EXP(-0.0937*AY25) -> 1 | BA25: =0.9864+0.3978*EXP(-1.3083*AY25) -> 0.9864
B26: 12 | C26: 24 | D26: 36 | E26: 48 | F26: 60 | G26: 72 | H26: 84 | I26: 96 | J26: 108 | K26: 120 | L26: 132 | M26: 144 | N26: 156 | S26: 12 | T26: 24 | U26: 36 | V26: 48 | W26: 60 | X26: 72 | Y26: 84 | Z26: 96 | AA26: 108 | AB26: 120 | AC26: 132 | AD26: 144 | AE26: 156 | AF26: 0.6, 0.4 | AY26: =AY25+12 -> 396 | AZ26: =1 + 9.8243 * EXP(-0.0937*AY26) -> 1 | BA26: =0.9864+0.3978*EXP(-1.3083*AY26) -> 0.9864
A27: Accident | B27: to | C27: to | D27: to | E27: to | F27: to | G27: to | H27: to | I27: to | J27: to | K27: to | L27: to | M27: to | N27: to | R27: Accident | S27: to | T27: to | U27: to | V27: to | W27: to | X27: to | Y27: to | Z27: to | AA27: to | AB27: to | AC27: to | AD27: to | AE27: to | AJ27: Accident | AY27: =AY26+12 -> 408 | AZ27: =1 + 9.8243 * EXP(-0.0937*AY27) -> 1 | BA27: =0.9864+0.3978*EXP(-1.3083*AY27) -> 0.9864
A28: Year | B28: 24 | C28: 36 | D28: 48 | E28: 60 | F28: 72 | G28: 84 | H28: 96 | I28: 108 | J28: 120 | K28: 132 | L28: 144 | M28: 156 | N28: Ultimate | R28: Year | S28: 24 | T28: 36 | U28: 48 | V28: 60 | W28: 72 | X28: 84 | Y28: 96 | Z28: 108 | AA28: 120 | AB28: 132 | AC28: 144 | AD28: 156 | AE28: Ultimate | AJ28: Year | AK28: 12 | AL28: 24 | AM28: 36 | AN28: 48 | AO28: 60 | AP28: 72 | AQ28: 84 | AR28: 96 | AS28: 108 | AT28: 120 | AU28: 132 | AV28: 144 | AW28: 156 | AY28: =AY27+12 -> 420 | AZ28: =1 + 9.8243 * EXP(-0.0937*AY28) -> 1 | BA28: =0.9864+0.3978*EXP(-1.3083*AY28) -> 0.9864
AY29: =AY28+12 -> 432 | AZ29: =1 + 9.8243 * EXP(-0.0937*AY29) -> 1 | BA29: =0.9864+0.3978*EXP(-1.3083*AY29) -> 0.9864
A30: =A8 -> 2003 | I30: =IFERROR(J8/I8,1) -> 1.0195489 | J30: =IFERROR(K8/J8,1) -> 1.009594 | K30: =IFERROR(L8/K8,1) -> 0.98104944 | L30: =IFERROR(M8/L8,1) -> 1.0191762 | M30: =IFERROR(N8/M8,1) -> 0.99009642 | N30: 1 | R30: =R8 -> 2003 | Z30: =IFERROR(AA8/Z8,1) -> 1.0254764 | AA30: =IFERROR(AB8/AA8,1) -> 1.0229286 | AB30: =IFERROR(AC8/AB8,1) -> 1 | AC30: =IFERROR(AD8/AC8,1) -> 1.0214605 | AD30: =IFERROR(AE8/AD8,1) -> 1.0069987 | AE30: 1.0000065 | AJ30: 2003 | AR30: 66618.247 | AS30: 68315.439 | AT30: 69881.816 | AU30: 69881.816 | AV30: 71381.512 | AW30: 71881.089 | AY30: =AY29+12 -> 444 | AZ30: =1 + 9.8243 * EXP(-0.0937*AY30) -> 1 | BA30: =0.9864+0.3978*EXP(-1.3083*AY30) -> 0.9864
A31: =A9 -> 2004 | H31: =IFERROR(I9/H9,1) -> 0.99300094 | I31: =IFERROR(J9/I9,1) -> 1.0471879 | J31: =IFERROR(K9/J9,1) -> 1.0096451 | K31: =IFERROR(L9/K9,1) -> 1.0252089 | L31: =IFERROR(M9/L9,1) -> 0.99174108 | R31: =R9 -> 2004 | Y31: =IFERROR(Z9/Y9,1) -> 1.015 | Z31: =IFERROR(AA9/Z9,1) -> 1.0373627 | AA31: =IFERROR(AB9/AA9,1) -> 1.0142946 | AB31: =IFERROR(AC9/AB9,1) -> 1.0353968 | AC31: =IFERROR(AD9/AC9,1) -> 1.0193841 | AJ31: 2004 | AQ31: 64521.02 | AR31: 65488.835 | AS31: 67935.673 | AT31: 68906.784 | AU31: 71345.865 | AV31: 72728.844 | AY31: =AY30+12 -> 456 | AZ31: =1 + 9.8243 * EXP(-0.0937*AY31) -> 1 | BA31: =0.9864+0.3978*EXP(-1.3083*AY31) -> 0.9864
A32: =A10 -> 2005 | G32: =IFERROR(H10/G10,1) -> 0.99200877 | H32: =IFERROR(I10/H10,1) -> 0.99798969 | I32: =IFERROR(J10/I10,1) -> 0.99346772 | J32: =IFERROR(K10/J10,1) -> 1.020305 | K32: =IFERROR(L10/K10,1) -> 0.99410921 | R32: =R10 -> 2005 | X32: =IFERROR(Y10/X10,1) -> 1.03 | Y32: =IFERROR(Z10/Y10,1) -> 1.022 | Z32: =IFERROR(AA10/Z10,1) -> 1.0034875 | AA32: =IFERROR(AB10/AA10,1) -> 1.0263355 | AB32: =IFERROR(AC10/AB10,1) -> 1.0115206 | AJ32: 2005 | AP32: 61869.596 | AQ32: 63725.684 | AR32: 65127.649 | AS32: 65354.779 | AT32: 67075.927 | AU32: 67848.685 | AY32: =AY31+12 -> 468 | AZ32: =1 + 9.8243 * EXP(-0.0937*AY32) -> 1 | BA32: =0.9864+0.3978*EXP(-1.3083*AY32) -> 0.9864
A33: =A11 -> 2006 | F33: =IFERROR(G11/F11,1) -> 0.99100041 | G33: =IFERROR(H11/G11,1) -> 0.9869932 | H33: =IFERROR(I11/H11,1) -> 1.0030126 | I33: =IFERROR(J11/I11,1) -> 1.0064509 | J33: =IFERROR(K11/J11,1) -> 0.98995928 | R33: =R11 -> 2006 | W33: =IFERROR(X11/W11,1) -> 1.06 | X33: =IFERROR(Y11/X11,1) -> 1.032 | Y33: =IFERROR(Z11/Y11,1) -> 1.025 | Z33: =IFERROR(AA11/Z11,1) -> 1.0235685 | AA33: =IFERROR(AB11/AA11,1) -> 1.0109163 | AJ33: 2006 | AO33: 55420.944 | AP33: 58746.2 | AQ33: 60626.079 | AR33: 62141.731 | AS33: 63606.318 | AT33: 64300.664 | AY33: =AY32+12 -> 480 | AZ33: =1 + 9.8243 * EXP(-0.0937*AY33) -> 1 | BA33: =0.9864+0.3978*EXP(-1.3083*AY33) -> 0.9864
A34: =A12 -> 2007 | E34: =IFERROR(F12/E12,1) -> 1.0010072 | F34: =IFERROR(G12/F12,1) -> 0.99499777 | G34: =IFERROR(H12/G12,1) -> 1.0030049 | H34: =IFERROR(I12/H12,1) -> 0.99000418 | I34: =IFERROR(J12/I12,1) -> 0.99447152 | R34: =R12 -> 2007 | V34: =IFERROR(W12/V12,1) -> 1.115 | W34: =IFERROR(X12/W12,1) -> 1.066 | X34: =IFERROR(Y12/X12,1) -> 1.04 | Y34: =IFERROR(Z12/Y12,1) -> 1.017 | Z34: =IFERROR(AA12/Z12,1) -> 1.011722 | AJ34: 2007 | AN34: 50694.623 | AO34: 56524.504 | AP34: 60255.122 | AQ34: 62665.327 | AR34: 63730.637 | AS34: 64477.685
A35: =A13 -> 2008 | D35: =IFERROR(E13/D13,1) -> 1.0349965 | E35: =IFERROR(F13/E13,1) -> 1.0039928 | F35: =IFERROR(G13/F13,1) -> 0.99300563 | G35: =IFERROR(H13/G13,1) -> 0.99799754 | H35: =IFERROR(I13/H13,1) -> 0.98999565 | R35: =R13 -> 2008 | U35: =IFERROR(V13/U13,1) -> 1.212 | V35: =IFERROR(W13/V13,1) -> 1.137 | W35: =IFERROR(X13/W13,1) -> 1.057 | X35: =IFERROR(Y13/X13,1) -> 1.03 | Y35: =IFERROR(Z13/Y13,1) -> 1.015 | AJ35: 2008 | AM35: 43162.458 | AN35: 52312.9 | AO35: 59479.767 | AP35: 62870.114 | AQ35: 64756.217 | AR35: 65727.56 | AZ35: =PRODUCT(AZ6:AZ33) -> 1.0000065
A36: =A14 -> 2009 | C36: =IFERROR(D14/C14,1) -> 1.0989969 | D36: =IFERROR(E14/D14,1) -> 1.033001 | E36: =IFERROR(F14/E14,1) -> 0.99599679 | F36: =IFERROR(G14/F14,1) -> 0.99500231 | G36: =IFERROR(H14/G14,1) -> 0.99600037 | R36: =R14 -> 2009 | T36: =IFERROR(U14/T14,1) -> 1.508 | U36: =IFERROR(V14/U14,1) -> 1.236 | V36: =IFERROR(W14/V14,1) -> 1.118 | W36: =IFERROR(X14/W14,1) -> 1.061 | X36: =IFERROR(Y14/X14,1) -> 1.027 | AJ36: 2009 | AL36: 29996.407 | AM36: 45234.582 | AN36: 55909.943 | AO36: 62507.317 | AP36: 66320.263 | AQ36: 68110.91
A37: =A15 -> 2010 | B37: =IFERROR(C15/B15,1) -> 1.3190005 | C37: =IFERROR(D15/C15,1) -> 1.1100023 | D37: =IFERROR(E15/D15,1) -> 1.0350041 | E37: =IFERROR(F15/E15,1) -> 0.99600051 | F37: =IFERROR(G15/F15,1) -> 1.0020007 | R37: =R15 -> 2010 | S37: =IFERROR(T15/S15,1) -> 2.657 | T37: =IFERROR(U15/T15,1) -> 1.55 | U37: =IFERROR(V15/U15,1) -> 1.23 | V37: =IFERROR(W15/V15,1) -> 1.117 | W37: =IFERROR(X15/W15,1) -> 1.06 | AJ37: 2010 | AK37: 10418.129 | AL37: 27680.969 | AM37: 42905.503 | AN37: 52773.768 | AO37: 58948.299 | AP37: 62485.197
A38: =A16 -> 2011 | B38: =IFERROR(C16/B16,1) -> 1.3679913 | C38: =IFERROR(D16/C16,1) -> 1.1129914 | D38: =IFERROR(E16/D16,1) -> 1.028009 | E38: =IFERROR(F16/E16,1) -> 1.009 | R38: =R16 -> 2011 | S38: =IFERROR(T16/S16,1) -> 2.735 | T38: =IFERROR(U16/T16,1) -> 1.546 | U38: =IFERROR(V16/U16,1) -> 1.236 | V38: =IFERROR(W16/V16,1) -> 1.115 | AJ38: 2011 | AK38: 10469.768 | AL38: 28634.815 | AM38: 44269.423 | AN38: 54717.007 | AO38: 61009.463
A39: =A17 -> 2012 | B39: =C4/B17 -> 1.3903607 | C39: =IFERROR(D4/C4, 1) -> 1.1228936 | D39: =IFERROR(E4/D4,1) -> 1.0093552 | R39: =R17 -> 2012 | S39: =IFERROR(T17/S17,1) -> 2.8609914 | T39: =IFERROR(U17/T17,1) -> 1.5620206 | U39: =IFERROR(V17/U17,1) -> 1.2229791 | AJ39: 2012 | AK39: 9887.831 | AL39: 32289.085 | AM39: 50187.55 | AN39: 62041.374
A40: =A18 -> 2013 | B40: =IFERROR(C18/B18,1) -> 1.3449985 | C40: =IFERROR(D18/C18,1) -> 1.1489889 | R40: =R18 -> 2013 | S40: =IFERROR(T18/S18,1) -> 2.885 | T40: =IFERROR(U18/T18,1) -> 1.534 | AJ40: 2013 | AK40: 9300.4543 | AL40: 26831.811 | AM40: 41159.998
...

Sheet Base_Med_Tri
B2: Direct Accident Year Case Reported Loss Development Factors | Q2: Direct Accident Year Paid Loss Development Factors
B3: MEDICAL in $Thousands | Q3: MEDICAL in $Thousands
A5: Accident | P5: Accident
A6: Year | B6: 12 | C6: 24 | D6: 36 | E6: 48 | F6: 60 | G6: 72 | H6: 84 | I6: 96 | J6: 108 | K6: 120 | L6: 132 | M6: 144 | N6: 156 | O6: Ultimate | P6: Year | Q6: 12 | R6: 24 | S6: 36 | T6: 48 | U6: 60 | V6: 72 | W6: 84 | X6: 96 | Y6: 108 | Z6: 120 | AA6: 132 | AB6: 144 | AC6: 156 | AD6: Ultimate
AE7: reported | AF7: 1115654
A8: 2003 | I8: 68262 | J8: 72178 | K8: 74888 | L8: 74074 | M8: 75563 | N8: 74815 | O8: 74815 | P8: 2003 | X8: 64887 | Y8: 67429 | Z8: 69896 | AA8: 70624 | AB8: 72994 | AC8: 74815 | AD8: 74815 | AE8: paid | AF8: 1064910
A9: 2004 | H9: 73663 | I9: 73957 | J9: 76213 | K9: 76027 | L9: 77662 | M9: 76989 | N9: 77759 | O9: 78537 | P9: 2004 | W9: 69516 | X9: 69724 | Y9: 71554 | Z9: 71798 | AA9: 73621 | AB9: 74372 | AC9: 76227 | AD9: 78129
A10: 2005 | G10: 72589 | H10: 71790 | I10: 71360 | J10: 74329 | K10: 78580 | L10: 78953 | M10: 79378 | N10: 80172 | O10: 80974 | P10: 2005 | V10: 68244 | W10: 68585 | X10: 68928 | Y10: 70234 | Z10: 73194 | AA10: 75063 | AB10: 76687 | AC10: 78600 | AD10: 80561
A11: 2006 | F11: 76631 | G11: 76171 | H11: 75029 | I11: 75854 | J11: 78130 | K11: 78698 | L11: 79108 | M11: 79534 | N11: 80329 | O11: 81132 | P11: 2006 | U11: 69548 | V11: 70661 | W11: 71085 | X11: 71654 | Y11: 73177 | Z11: 73809 | AA11: 75327 | AB11: 76957 | AC11: 78877 | AD11: 80845
A12: 2007 | E12: 80418 | F12: 79292 | G12: 78420 | H12: 77087 | I12: 76856 | J12: 78151 | K12: 78558 | L12: 78967 | M12: 79392 | N12: 80186 | O12: 80988 | P12: 2007 | T12: 69857 | U12: 71394 | V12: 72036 | W12: 72252 | X12: 72469 | Y12: 73620 | Z12: 75264 | AA12: 76812 | AB12: 78473 | AC12: 80431 | AD12: 82438
A13: 2008 | D13: 79508 | E13: 79031 | F13: 77766 | G13: 76988 | H13: 75988 | I13: 75760 | J13: 77609 | K13: 78012 | L13: 78418 | M13: 78841 | N13: 79629 | O13: 80425 | P13: 2008 | S13: 65954 | T13: 69186 | U13: 70639 | V13: 71204 | W13: 71631 | X13: 71918 | Y13: 73523 | Z13: 75164 | AA13: 76710 | AB13: 78370 | AC13: 80325 | AD13: 82329
A14: 2009 | C14: 82756 | D14: 82839 | E14: 83088 | F14: 81758 | G14: 81104 | H14: 79969 | I14: 82329 | J14: 84338 | K14: 84777 | L14: 85218 | M14: 85677 | N14: 86534 | O14: 87399 | P14: 2009 | R14: 63478 | S14: 70968 | T14: 73736 | U14: 74916 | V14: 75365 | W14: 75516 | X14: 77330 | Y14: 79056 | Z14: 80821 | AA14: 82484 | AB14: 84268 | AC14: 86370 | AD14: 88525
A15: 2010 | B15: 66170 | C15: 81984 | D15: 83542 | E15: 82707 | F15: 80639 | G15: 79772 | H15: 79821.15 | I15: 82177 | J15: 84183 | K15: 84621 | L15: 85061 | M15: 85519 | N15: 86374 | O15: 87238 | P15: 2010 | Q15: 32447 | R15: 62071 | S15: 69395 | T15: 72241 | U15: 73324 | V15: 73984 | W15: 74324.24 | X15: 76110 | Y15: 77809 | Z15: 79545 | AA15: 81182 | AB15: 82938 | AC15: 85007 | AD15: 87128
A16: 2011 | B16: 67819 | C16: 85655 | D16: 86083 | E16: 83845 | F16: 83510 | G16: 83509.69 | H16: 83561.11 | I16: 86028 | J16: 88127 | K16: 88586 | L16: 89047 | M16: 89526 | N16: 90422 | O16: 91326 | P16: 2011 | Q16: 33009 | R16: 64598 | S16: 71963 | T16: 74625 | U16: 75968 | V16: 76299.73 | W16: 76650.56 | X16: 78492 | Y16: 80244 | Z16: 82035 | AA16: 83722 | AB16: 85534 | AC16: 87668 | AD16: 89855
A17: 2012 | B17: 70617 | C17: 96201 | D17: 101672 | E17: 99409 | F17: 101574.7 | G17: 101574.7 | H17: 101637.2 | I17: 104637 | J17: 107191 | K17: 107749 | L17: 108310 | M17: 108893 | N17: 109982 | O17: 111082 | P17: 2012 | Q17: 34991 | R17: 71657 | S17: 81323 | T17: 88999 | U17: 89846.97 | V17: 90238.83 | W17: 90653.75 | X17: 92831 | Y17: 94904 | Z17: 97022 | AA17: 99018 | AB17: 101160 | AC17: 103684 | AD17: 106271
A18: 2013 | B18: 65449 | C18: 80633 | D18: 82729 | E18: 82729.5 | F18: 84532.2 | G18: 84532.2 | H18: 84584.25 | I18: 87081 | J18: 89206 | K18: 89670 | L18: 90137 | M18: 90622 | N18: 91529 | O18: 92444 | P18: 2013 | Q18: 31785 | R18: 62331 | S18: 69375 | T18: 70647.18 | U18: 71320.6 | V18: 71631.66 | W18: 71961.02 | X18: 73690 | Y18: 75335 | Z18: 77016 | AA18: 78600 | AB18: 80301 | AC18: 82304 | AD18: 84358
A19: 2014 | B19: 63580 | C19: 84816 | D19: 84816.006 | E19: 84816.01 | F19: 86664.18 | G19: 86664.18 | H19: 86717.54 | I19: 89277 | J19: 91456 | K19: 91932 | L19: 92410 | M19: 92908 | N19: 93837 | O19: 94775 | P19: 2014 | Q19: 33131 | R19: 64406 | S19: 67841.735 | T19: 69086.05 | U19: 69744.58 | V19: 70048.77 | W19: 70370.86 | X19: 72061 | Y19: 73670 | Z19: 75314 | AA19: 76863 | AB19: 78526 | AC19: 80485 | AD19: 82494
A20: 2015 | B20: 66114 | C20: 66687.73 | D20: 66687.731 | E20: 66687.73 | F20: 68140.88 | G20: 68140.88 | H20: 68182.84 | I20: 70195 | J20: 71909 | K20: 72283 | L20: 72659 | M20: 73050 | N20: 73781 | O20: 74518 | P20: 2015 | Q20: 32877 | R20: 36820.97 | S20: 38785.173 | T20: 39496.55 | U20: 39873.03 | V20: 40046.93 | W20: 40231.07 | X20: 41198 | Y20: 42117 | Z20: 43057 | AA20: 43943 | AB20: 44894 | AC20: 46014 | AD20: 47162
B24: Target - Direct Accident Year Case Reported Loss Development Factors | Q24: Target - Direct Accident Year Paid Loss Development Factors
B25: MEDICAL | Q25: MEDICAL
B26: 12 | C26: 24 | D26: 36 | E26: 48 | F26: 60 | G26: 72 | H26: 84 | I26: 96 | J26: 108 | K26: 120 | L26: 132 | M26: 144 | N26: 156 | Q26: 12 | R26: 24 | S26: 36 | T26: 48 | U26: 60 | V26: 72 | W26: 84 | X26: 96 | Y26: 108 | Z26: 120 | AA26: 132 | AB26: 144 | AC26: 156
A27: Accident | B27: to | C27: to | D27: to | E27: to | F27: to | G27: to | H27: to | I27: to | J27: to | K27: to | L27: to | M27: to | N27: to | P27: Accident | Q27: to | R27: to | S27: to | T27: to | U27: to | V27: to | W27: to | X27: to | Y27: to | Z27: to | AA27: to | AB27: to | AC27: to
A28: Year | B28: 24 | C28: 36 | D28: 48 | E28: 60 | F28: 72 | G28: 84 | H28: 96 | I28: 108 | J28: 120 | K28: 132 | L28: 144 | M28: 156 | N28: Ultimate | P28: Year | Q28: 24 | R28: 36 | S28: 48 | T28: 60 | U28: 72 | V28: 84 | W28: 96 | X28: 108 | Y28: 120 | Z28: 132 | AA28: 144 | AB28: 156 | AC28: Ultimate
A30: =A8 -> 2003 | I30: =IFERROR(J8/I8,1) -> 1.0573672 | J30: =IFERROR(K8/J8,1) -> 1.0375461 | K30: =IFERROR(L8/K8,1) -> 0.98913043 | L30: =IFERROR(M8/L8,1) -> 1.0201015 | M30: =IFERROR(N8/M8,1) -> 0.99010098 | P30: =P8 -> 2003 | X30: =IFERROR(Y8/X8,1) -> 1.0391758 | Y30: =IFERROR(Z8/Y8,1) -> 1.0365866 | Z30: =IFERROR(AA8/Z8,1) -> 1.0104155 | AA30: =IFERROR(AB8/AA8,1) -> 1.033558 | AB30: =IFERROR(AC8/AB8,1) -> 1.0249473
A31: =A9 -> 2004 | H31: =IFERROR(I9/H9,1) -> 1.0039911 | I31: =IFERROR(J9/I9,1) -> 1.0305042 | J31: =IFERROR(K9/J9,1) -> 0.99755947 | K31: =IFERROR(L9/K9,1) -> 1.0215055 | L31: =IFERROR(M9/L9,1) -> 0.99133424 | P31: =P9 -> 2004 | W31: =IFERROR(X9/W9,1) -> 1.0029921 | X31: =IFERROR(Y9/X9,1) -> 1.0262463 | Y31: =IFERROR(Z9/Y9,1) -> 1.00341 | Z31: =IFERROR(AA9/Z9,1) -> 1.0253907 | AA31: =IFERROR(AB9/AA9,1) -> 1.0102009
A32: =A10 -> 2005 | G32: =IFERROR(H10/G10,1) -> 0.98899282 | H32: =IFERROR(I10/H10,1) -> 0.99401031 | I32: =IFERROR(J10/I10,1) -> 1.0416059 | J32: =IFERROR(K10/J10,1) -> 1.0571917 | K32: =IFERROR(L10/K10,1) -> 1.0047468 | P32: =P10 -> 2005 | V32: =IFERROR(W10/V10,1) -> 1.0049968 | W32: =IFERROR(X10/W10,1) -> 1.0050011 | X32: =IFERROR(Y10/X10,1) -> 1.0189473 | Y32: =IFERROR(Z10/Y10,1) -> 1.0421448 | Z32: =IFERROR(AA10/Z10,1) -> 1.0255349
A33: =A11 -> 2006 | F33: =IFERROR(G11/F11,1) -> 0.99399721 | G33: =IFERROR(H11/G11,1) -> 0.98500742 | H33: =IFERROR(I11/H11,1) -> 1.0109957 | I33: =IFERROR(J11/I11,1) -> 1.030005 | J33: =IFERROR(K11/J11,1) -> 1.0072699 | P33: =P11 -> 2006 | U33: =IFERROR(V11/U11,1) -> 1.0160033 | V33: =IFERROR(W11/V11,1) -> 1.0060005 | W33: =IFERROR(X11/W11,1) -> 1.0080045 | X33: =IFERROR(Y11/X11,1) -> 1.0212549 | Y33: =IFERROR(Z11/Y11,1) -> 1.0086366
A34: =A12 -> 2007 | E34: =IFERROR(F12/E12,1) -> 0.98599816 | F34: =IFERROR(G12/F12,1) -> 0.98900267 | G34: =IFERROR(H12/G12,1) -> 0.98300179 | H34: =IFERROR(I12/H12,1) -> 0.99700339 | I34: =IFERROR(J12/I12,1) -> 1.0168497 | P34: =P12 -> 2007 | T34: =IFERROR(U12/T12,1) -> 1.0220021 | U34: =IFERROR(V12/U12,1) -> 1.0089924 | V34: =IFERROR(W12/V12,1) -> 1.0029985 | W34: =IFERROR(X12/W12,1) -> 1.0030034 | X34: =IFERROR(Y12/X12,1) -> 1.0158827
A35: =A13 -> 2008 | D35: =IFERROR(E13/D13,1) -> 0.9940006 | E35: =IFERROR(F13/E13,1) -> 0.98399362 | F35: =IFERROR(G13/F13,1) -> 0.98999563 | G35: =IFERROR(H13/G13,1) -> 0.98701096 | H35: =IFERROR(I13/H13,1) -> 0.99699953 | P35: =P13 -> 2008 | S35: =IFERROR(T13/S13,1) -> 1.0490039 | T35: =IFERROR(U13/T13,1) -> 1.0210014 | U35: =IFERROR(V13/U13,1) -> 1.0079984 | V35: =IFERROR(W13/V13,1) -> 1.0059969 | W35: =IFERROR(X13/W13,1) -> 1.0040066
A36: =A14 -> 2009 | C36: =IFERROR(D14/C14,1) -> 1.0010029 | D36: =IFERROR(E14/D14,1) -> 1.0030058 | E36: =IFERROR(F14/E14,1) -> 0.98399288 | F36: =IFERROR(G14/F14,1) -> 0.99200078 | G36: =IFERROR(H14/G14,1) -> 0.98600562 | P36: =P14 -> 2009 | R36: =IFERROR(S14/R14,1) -> 1.1179936 | S36: =IFERROR(T14/S14,1) -> 1.0390035 | T36: =IFERROR(U14/T14,1) -> 1.016003 | U36: =IFERROR(V14/U14,1) -> 1.0059934 | V36: =IFERROR(W14/V14,1) -> 1.0020036
A37: =A15 -> 2010 | B37: =IFERROR(C15/B15,1) -> 1.2389905 | C37: =IFERROR(D15/C15,1) -> 1.0190037 | D37: =IFERROR(E15/D15,1) -> 0.99000503 | E37: =IFERROR(F15/E15,1) -> 0.97499607 | F37: =IFERROR(G15/F15,1) -> 0.98924838 | P37: =P15 -> 2010 | Q37: =IFERROR(R15/Q15,1) -> 1.9129966 | R37: =IFERROR(S15/R15,1) -> 1.1179939 | S37: =IFERROR(T15/S15,1) -> 1.0410116 | T37: =IFERROR(U15/T15,1) -> 1.0149915 | U37: =IFERROR(V15/U15,1) -> 1.0090011
A38: =A16 -> 2011 | B38: =IFERROR(C16/B16,1) -> 1.2629941 | C38: =IFERROR(D16/C16,1) -> 1.0049968 | D38: =IFERROR(E16/D16,1) -> 0.97400184 | E38: =IFERROR(F16/E16,1) -> 0.99600453 | P38: =P16 -> 2011 | Q38: =IFERROR(R16/Q16,1) -> 1.9569814 | R38: =IFERROR(S16/R16,1) -> 1.1140128 | S38: =IFERROR(T16/S16,1) -> 1.0369912 | T38: =IFERROR(U16/T16,1) -> 1.0179966
A39: =A17 -> 2012 | B39: =IFERROR(C17/B17,1) -> 1.3622924 | C39: =IFERROR(D17/C17,1) -> 1.0568705 | D39: =IFERROR(E17/D17,1) -> 0.97774215 | P39: =P17 -> 2012 | Q39: =IFERROR(R17/Q17,1) -> 2.0478695 | R39: =IFERROR(S17/R17,1) -> 1.1348926 | S39: =IFERROR(T17/S17,1) -> 1.094389
A40: =A18 -> 2013 | B40: =IFERROR(C18/B18,1) -> 1.2319974 | C40: =IFERROR(D18/C18,1) -> 1.0259943 | P40: =P18 -> 2013 | Q40: =IFERROR(R18/Q18,1) -> 1.9610193 | R40: =IFERROR(S18/R18,1) -> 1.1130096
A41: =A19 -> 2014 | B41: =IFERROR(C19/B19,1) -> 1.3340044 | P41: =P19 -> 2014 | Q41: =IFERROR(R19/Q19,1) -> 1.94398
A43: Incremental Averages | P43: Incremental Averages
A44: 2 Year | B44: =AVERAGE(B40:B41) -> 1.2830009 | C44: =AVERAGE(C39:C40) -> 1.0414324 | D44: =AVERAGE(D38:D39) -> 0.97587199 | E44: =AVERAGE(E37:E38) -> 0.9855003 | F44: =AVERAGE(F36:F37) -> 0.99062458 | G44: =AVERAGE(G35:G36) -> 0.98650829 | H44: =AVERAGE(H34:H35) -> 0.99700146 | I44: =AVERAGE(I33:I34) -> 1.0234274 | J44: =AVERAGE(J32:J33) -> 1.0322308 | K44: =AVERAGE(K31:K32) -> 1.0131261 | L44: =AVERAGE(L30:L31) -> 1.0057179 | M44: =M$48 -> 0.99010098 | P44: 2 Year | Q44: =AVERAGE(Q40:Q41) -> 1.9524997 | R44: =AVERAGE(R39:R40) -> 1.1239511 | S44: =AVERAGE(S38:S39) -> 1.0656901 | T44: =AVERAGE(T37:T38) -> 1.0164941 | U44: =AVERAGE(U36:U37) -> 1.0074973 | V44: =AVERAGE(V35:V36) -> 1.0040002 | W44: =AVERAGE(W34:W35) -> 1.003505 | X44: =AVERAGE(X34:X35) -> 1.0158827 | Y44: =AVERAGE(Y32:Y33) -> 1.0253907 | Z44: =AVERAGE(Z31:Z32) -> 1.0254628 | AA44: =AVERAGE(AA30:AA31) -> 1.0218794 | AB44: =AB$48 -> 1.0249473
A45: 3 Year | B45: =AVERAGE(B39:B41) -> 1.3094314 | C45: =AVERAGE(C38:C40) -> 1.0292872 | D45: =AVERAGE(D37:D39) -> 0.980583 | E45: =AVERAGE(E36:E38) -> 0.98499783 | F45: =AVERAGE(F35:F37) -> 0.99041493 | G45: =AVERAGE(G34:G36) -> 0.98533946 | H45: =AVERAGE(H33:H35) -> 1.0016662 | I45: =AVERAGE(I32:I34) -> 1.0294869 | J45: =AVERAGE(J31:J33) -> 1.0206737 | K45: =AVERAGE(K30:K32) -> 1.0051276 | L45: =L$48 -> 1.0057179 | M45: =M$48 -> 0.99010098 | P45: 3 Year | Q45: =AVERAGE(Q39:Q41) -> 1.9842896 | R45: =AVERAGE(R38:R40) -> 1.1206383 | S45: =AVERAGE(S37:S39) -> 1.057464 | T45: =AVERAGE(T36:T38) -> 1.0163304 | U45: =AVERAGE(U35:U37) -> 1.0076643 | V45: =AVERAGE(V34:V36) -> 1.0036663 | W45: =AVERAGE(W33:W35) -> 1.0050048 | X45: =AVERAGE(X33:X35) -> 1.0185688 | Y45: =AVERAGE(Y31:Y33) -> 1.0180638 | Z45: =AVERAGE(Z30:Z32) -> 1.020447 | AA45: =AA$48 -> 1.0218794 | AB45: =AB$48 -> 1.0249473
A46: 4 Year | B46: =AVERAGE(B38:B41) -> 1.2978221 | C46: =AVERAGE(C37:C40) -> 1.0267163 | D46: =AVERAGE(D36:D39) -> 0.98618871 | E46: =AVERAGE(E35:E38) -> 0.98474678 | F46: =AVERAGE(F34:F37) -> 0.99006187 | G46: =AVERAGE(G33:G36) -> 0.98525645 | H46: =AVERAGE(H32:H35) -> 0.99975224 | I46: =AVERAGE(I31:I34) -> 1.0297412 | J46: =AVERAGE(J30:J33) -> 1.0248918 | K46: =K$48 -> 1.0051276 | L46: =L$48 -> 1.0057179 | M46: =M$48 -> 0.99010098 | P46: 4 Year | Q46: =AVERAGE(Q38:Q41) -> 1.9774625 | R46: =AVERAGE(R37:R40) -> 1.1199772 | S46: =AVERAGE(S36:S39) -> 1.0528488 | T46: =AVERAGE(T35:T38) -> 1.0174981 | U46: =AVERAGE(U34:U37) -> 1.0079963 | V46: =AVERAGE(V33:V36) -> 1.0042499 | W46: =AVERAGE(W32:W35) -> 1.0050039 | X46: =AVERAGE(X32:X35) -> 1.018695 | Y46: =AVERAGE(Y30:Y33) -> 1.0226945 | Z46: =Z$48 -> 1.020447 | AA46: =AA$48 -> 1.0218794 | AB46: =AB$48 -> 1.0249473
A47: 5 Year | B47: =AVERAGE(B37:B41) -> 1.2860558 | C47: =AVERAGE(C36:C40) -> 1.0215737 | D47: =AVERAGE(D35:D39) -> 0.98775109 | E47: =AVERAGE(E34:E38) -> 0.98499705 | F47: =AVERAGE(F33:F37) -> 0.99084893 | G47: =AVERAGE(G32:G36) -> 0.98600372 | H47: =AVERAGE(H31:H35) -> 1.0006 | I47: =AVERAGE(I30:I34) -> 1.0352664 | J47: =J$48 -> 1.0248918 | K47: =K$48 -> 1.0051276 | L47: =L$48 -> 1.0057179 | M47: =M$48 -> 0.99010098 | P47: 5 Year | Q47: =AVERAGE(Q37:Q41) -> 1.9645694 | R47: =AVERAGE(R36:R40) -> 1.1195805 | S47: =AVERAGE(S35:S39) -> 1.0520798 | T47: =AVERAGE(T34:T38) -> 1.0183989 | U47: =AVERAGE(U33:U37) -> 1.0095977 | V47: =AVERAGE(V32:V36) -> 1.0043992 | W47: =AVERAGE(W31:W35) -> 1.0046015 | X47: =AVERAGE(X30:X34) -> 1.0243014 | Y47: =Y$48 -> 1.0226945 | Z47: =Z$48 -> 1.020447 | AA47: =AA$48 -> 1.0218794 | AB47: =AB$48 -> 1.0249473
...

Sheet % of Ult
B3: Percent Paid | D3: Percent Reported
A4: Age | B4: Indemnity | C4: Medical | D4: Indemnity | E4: Medical
B5: Ind Paid | C5: Med Paid | D5: Ind Rep | E5: Med Rep
A6: 12 | B6: =1/HLOOKUP($A6,Base_Indem_Tri!$S$6:$AE$57,52,FALSE) -> 0.13157496 | C6: =1/HLOOKUP($A6,Base_Med_Tri!$Q$6:$AC$57,52,FALSE) -> 0.37140677 | D6: =1/HLOOKUP($A6,Base_Indem_Tri!$B$6:$N$57,52,FALSE) -> 0.65517911 | E6: =1/HLOOKUP($A6,Base_Med_Tri!$B$6:$N$57,52,FALSE) -> 0.69960779
A7: =+A6+12 -> 24 | B7: =1/HLOOKUP($A7,Base_Indem_Tri!$S$6:$AE$57,52,FALSE) -> 0.37237007 | C7: =1/HLOOKUP($A7,Base_Med_Tri!$Q$6:$AC$57,52,FALSE) -> 0.7301857 | D7: =1/HLOOKUP($A7,Base_Indem_Tri!$B$6:$N$57,52,FALSE) -> 0.89614317 | E7: =1/HLOOKUP($A7,Base_Med_Tri!$B$6:$N$57,52,FALSE) -> 0.90039522
A8: =+A7+12 -> 36 | B8: =1/HLOOKUP($A8,Base_Indem_Tri!$S$6:$AE$57,52,FALSE) -> 0.5746434 | C8: =1/HLOOKUP($A8,Base_Med_Tri!$Q$6:$AC$57,52,FALSE) -> 0.81780799 | D8: =1/HLOOKUP($A8,Base_Indem_Tri!$B$6:$N$57,52,FALSE) -> 0.99946467 | E8: =1/HLOOKUP($A8,Base_Med_Tri!$B$6:$N$57,52,FALSE) -> 0.90849878
A9: =+A8+12 -> 48 | B9: =1/HLOOKUP($A9,Base_Indem_Tri!$S$6:$AE$57,52,FALSE) -> 0.70594581 | C9: =1/HLOOKUP($A9,Base_Med_Tri!$Q$6:$AC$57,52,FALSE) -> 0.86115181 | D9: =1/HLOOKUP($A9,Base_Indem_Tri!$B$6:$N$57,52,FALSE) -> 1.0229072 | E9: =1/HLOOKUP($A9,Base_Med_Tri!$B$6:$N$57,52,FALSE) -> 0.90849878
A10: =+A9+12 -> 60 | B10: =1/HLOOKUP($A10,Base_Indem_Tri!$S$6:$AE$57,52,FALSE) -> 0.79023574 | C10: =1/HLOOKUP($A10,Base_Med_Tri!$Q$6:$AC$57,52,FALSE) -> 0.87665254 | D10: =1/HLOOKUP($A10,Base_Indem_Tri!$B$6:$N$57,52,FALSE) -> 1.0215399 | E10: =1/HLOOKUP($A10,Base_Med_Tri!$B$6:$N$57,52,FALSE) -> 0.90849878
A11: =+A10+12 -> 72 | B11: =1/HLOOKUP($A11,Base_Indem_Tri!$S$6:$AE$57,52,FALSE) -> 0.83808452 | C11: =1/HLOOKUP($A11,Base_Med_Tri!$Q$6:$AC$57,52,FALSE) -> 0.88541907 | D11: =1/HLOOKUP($A11,Base_Indem_Tri!$B$6:$N$57,52,FALSE) -> 1.0157532 | E11: =1/HLOOKUP($A11,Base_Med_Tri!$B$6:$N$57,52,FALSE) -> 0.92848575
A12: =+A11+12 -> 84 | B12: =1/HLOOKUP($A12,Base_Indem_Tri!$S$6:$AE$57,52,FALSE) -> 0.86440037 | C12: =1/HLOOKUP($A12,Base_Med_Tri!$Q$6:$AC$57,52,FALSE) -> 0.88896074 | D12: =1/HLOOKUP($A12,Base_Indem_Tri!$B$6:$N$57,52,FALSE) -> 1.0133869 | E12: =1/HLOOKUP($A12,Base_Med_Tri!$B$6:$N$57,52,FALSE) -> 0.92848575
A13: =+A12+12 -> 96 | B13: =1/HLOOKUP($A13,Base_Indem_Tri!$S$6:$AE$57,52,FALSE) -> 0.880435 | C13: =1/HLOOKUP($A13,Base_Med_Tri!$Q$6:$AC$57,52,FALSE) -> 0.89340555 | D13: =1/HLOOKUP($A13,Base_Indem_Tri!$B$6:$N$57,52,FALSE) -> 1.0059518 | E13: =1/HLOOKUP($A13,Base_Med_Tri!$B$6:$N$57,52,FALSE) -> 0.92941424
A14: =+A13+12 -> 108 | B14: =1/HLOOKUP($A14,Base_Indem_Tri!$S$6:$AE$57,52,FALSE) -> 0.8965102 | C14: =1/HLOOKUP($A14,Base_Med_Tri!$Q$6:$AC$57,52,FALSE) -> 0.91484728 | D14: =1/HLOOKUP($A14,Base_Indem_Tri!$B$6:$N$57,52,FALSE) -> 1.0128162 | E14: =1/HLOOKUP($A14,Base_Med_Tri!$B$6:$N$57,52,FALSE) -> 0.95729667
A15: =+A14+12 -> 120 | B15: =1/HLOOKUP($A15,Base_Indem_Tri!$S$6:$AE$57,52,FALSE) -> 0.91212644 | C15: =1/HLOOKUP($A15,Base_Med_Tri!$Q$6:$AC$57,52,FALSE) -> 0.93497392 | D15: =1/HLOOKUP($A15,Base_Indem_Tri!$B$6:$N$57,52,FALSE) -> 1.0126159 | E15: =1/HLOOKUP($A15,Base_Med_Tri!$B$6:$N$57,52,FALSE) -> 0.98027179
A16: =+A15+12 -> 132 | B16: =1/HLOOKUP($A16,Base_Indem_Tri!$S$6:$AE$57,52,FALSE) -> 0.97376172 | C16: =1/HLOOKUP($A16,Base_Med_Tri!$Q$6:$AC$57,52,FALSE) -> 0.95460837 | D16: =1/HLOOKUP($A16,Base_Indem_Tri!$B$6:$N$57,52,FALSE) -> 1.0066508 | E16: =1/HLOOKUP($A16,Base_Med_Tri!$B$6:$N$57,52,FALSE) -> 0.98517314
A17: =+A16+12 -> 144 | B17: =1/HLOOKUP($A17,Base_Indem_Tri!$S$6:$AE$57,52,FALSE) -> 0.9930422 | C17: =1/HLOOKUP($A17,Base_Med_Tri!$Q$6:$AC$57,52,FALSE) -> 0.97560976 | D17: =1/HLOOKUP($A17,Base_Indem_Tri!$B$6:$N$57,52,FALSE) -> 1.0121457 | E17: =1/HLOOKUP($A17,Base_Med_Tri!$B$6:$N$57,52,FALSE) -> 0.99009901

Sheet Catastrophe
B2: Catastrophe event background
B3: Occurred on 12/29/2012 setting up fireworks for NYE, so nothing paid or reserved in year 1. Some fatalities were settled indemnity in year 2.
B4: All claims were able to be settled in year 4 with final payments and savings realized on reserves. This data is included in the triangles.
A8: In Thousands | B8: 12 | C8: 24 | D8: 36 | E8: 48 | F8: 60
A9: Indemnity Reported | B9: 0 | C9: 5500 | D9: 9000 | E9: 8000 | F9: 8000
A10: Indemnity Paid | B10: 0 | C10: 4000 | D10: 6000 | E10: 8000 | F10: 8000
A12: Medical Reported | B12: 0 | C12: 8000 | D12: 14000 | E12: 12000 | F12: 12000
A13: Medical Paid | B13: 0 | C13: 5000 | D13: 7000 | E13: 12000 | F13: 12000
